<?xml version="1.0"?>
<!-- 
	this URDF file made by massyakur 
	for "Robotlar icin Matematik Temelleri" lesson
	Project 1
 -->
<robot name="cncrobotsimple">
  
  <!-- Colors -->
	<material name="red">
		<color rgba="1 0 0 0.1" />
	</material>
	<material name="green">
		<color rgba="0 1 0 0.1" />
	</material>
	<material name="blue">
		<color rgba="0 0 1 0.1" />
	</material>
	<material name="aqua">
		<color rgba="0 1 1 0.1" />
	</material>
	<material name="purple">
		<color rgba="1 0 1 0.1" />
	</material>

  <!-- Links -->
  <link name="base_link" />

  <link name="link0">
    <visual>
      <geometry>
        <box size="2 0.1 0.1" />
      </geometry>
      <origin xyz="0 0 0" />
      <material name="aqua" />
    </visual>
  </link>

  <link name="link1">
    <visual>
      <geometry>
        <box size="0.2 0.1 0.1" />
      </geometry>
      <origin xyz="0 0 0" />
      <material name="red" />
    </visual>
  </link>

  <link name="link2">
    <visual>
      <geometry>
        <box size="0.1 2 0.1" />
      </geometry>
      <origin xyz="0 0 0" />
      <material name="green" />
    </visual>
  </link>

  <link name="link3">
    <visual>
      <geometry>
        <box size="0.3 0.1 0.1" />
      </geometry>
      <origin xyz="0 0 0" />
      <material name="purple" />
    </visual>
  </link>

  <link name="end">
    <visual>
      <geometry>
        <cylinder radius = "0.05" length="0.2" />
      </geometry>
      <material name="blue" />
    </visual>
  </link>

  <!-- Joints -->
  <joint name="q0" type="fixed">
    <parent link="base_link" />
    <child link="link0" />
    <axis xyz="0 0 0" />
  </joint>

  <joint name="q1" type="prismatic">
    <parent link="link0" />
    <child link="link1" />
    <limit effort="100" velocity="1.0" lower="0" upper="2" />
    <origin xyz="-1 0 0.1" />
    <axis xyz="1 0 0" />
  </joint>
  
  <joint name="q2" type="prismatic">
    <parent link="link1" />
    <child link="link2" />
    <limit effort="100" velocity="1.0" lower="-1.8" upper="0" />
    <origin xyz="0 1 0" />
    <axis xyz="0 1 0" />
  </joint>

  <joint name="q3" type="revolute">
    <parent link="link2" />
    <child link="link3" />
    <limit lower="-1.57" upper="1.57" effort="10" velocity="1"/>
    <origin xyz="0 1 0" rpy="0 0 0" />
    <axis xyz="0 1 0" />
  </joint>  

  <joint name="notajoint" type="fixed">
    <parent link="link3" />
    <child link="end" />
    <origin xyz="0 0.1 0" />
  </joint>
  
</robot>
